Traceback (most recent call last):
  File "/Users/rblack/_dev/live-2022/.direnv/python-3.10.4/lib/python3.10/site-packages/jupyter_cache/executors/utils.py", line 51, in single_nb_execution
    executenb(
  File "/Users/rblack/_dev/live-2022/.direnv/python-3.10.4/lib/python3.10/site-packages/nbclient/client.py", line 1093, in execute
    return NotebookClient(nb=nb, resources=resources, km=km, **kwargs).execute()
  File "/Users/rblack/_dev/live-2022/.direnv/python-3.10.4/lib/python3.10/site-packages/nbclient/util.py", line 84, in wrapped
    return just_run(coro(*args, **kwargs))
  File "/Users/rblack/_dev/live-2022/.direnv/python-3.10.4/lib/python3.10/site-packages/nbclient/util.py", line 62, in just_run
    return loop.run_until_complete(coro)
  File "/usr/local/Cellar/python@3.10/3.10.4/Frameworks/Python.framework/Versions/3.10/lib/python3.10/asyncio/base_events.py", line 646, in run_until_complete
    return future.result()
  File "/Users/rblack/_dev/live-2022/.direnv/python-3.10.4/lib/python3.10/site-packages/nbclient/client.py", line 559, in async_execute
    await self.async_execute_cell(
  File "/Users/rblack/_dev/live-2022/.direnv/python-3.10.4/lib/python3.10/site-packages/nbclient/client.py", line 854, in async_execute_cell
    self._check_raise_for_error(cell, exec_reply)
  File "/Users/rblack/_dev/live-2022/.direnv/python-3.10.4/lib/python3.10/site-packages/nbclient/client.py", line 756, in _check_raise_for_error
    raise CellExecutionError.from_cell_and_msg(cell, exec_reply_content)
nbclient.exceptions.CellExecutionError: An error occurred while executing the following cell:
------------------
tQm = 4.5
tNm = 10
tx1 = 2
ty1 = 1.5
tx2 = 8
ty2 = 1
from mmtime.utils import show_curve
n = np.linspace(0,tNm, 50)
Q = []
for nx in n:
    Q.append(torque(nx,tQm,tx1,ty1,tx2,ty2,tNm))
show_curve(n,Q,"Analytical Torque Curve","N","Q")
------------------

[0;31m---------------------------------------------------------------------------[0m
[0;31mNameError[0m                                 Traceback (most recent call last)
[0;32m/var/folders/ws/5h_x4h713cg8w0jmrm5_tfzc0000gn/T/ipykernel_61364/1047786378.py[0m in [0;36m<module>[0;34m[0m
[1;32m      6[0m [0mty2[0m [0;34m=[0m [0;36m1[0m[0;34m[0m[0;34m[0m[0m
[1;32m      7[0m [0;32mfrom[0m [0mmmtime[0m[0;34m.[0m[0mutils[0m [0;32mimport[0m [0mshow_curve[0m[0;34m[0m[0;34m[0m[0m
[0;32m----> 8[0;31m [0mn[0m [0;34m=[0m [0mnp[0m[0;34m.[0m[0mlinspace[0m[0;34m([0m[0;36m0[0m[0;34m,[0m[0mtNm[0m[0;34m,[0m [0;36m50[0m[0;34m)[0m[0;34m[0m[0;34m[0m[0m
[0m[1;32m      9[0m [0mQ[0m [0;34m=[0m [0;34m[[0m[0;34m][0m[0;34m[0m[0;34m[0m[0m
[1;32m     10[0m [0;32mfor[0m [0mnx[0m [0;32min[0m [0mn[0m[0;34m:[0m[0;34m[0m[0;34m[0m[0m

[0;31mNameError[0m: name 'np' is not defined
NameError: name 'np' is not defined

