Traceback (most recent call last):
  File "/Users/rblack/_dev/nffs-symposium/live-2022/.direnv/python-3.8.12/lib/python3.8/site-packages/jupyter_cache/executors/utils.py", line 51, in single_nb_execution
    executenb(
  File "/Users/rblack/_dev/nffs-symposium/live-2022/.direnv/python-3.8.12/lib/python3.8/site-packages/nbclient/client.py", line 1093, in execute
    return NotebookClient(nb=nb, resources=resources, km=km, **kwargs).execute()
  File "/Users/rblack/_dev/nffs-symposium/live-2022/.direnv/python-3.8.12/lib/python3.8/site-packages/nbclient/util.py", line 84, in wrapped
    return just_run(coro(*args, **kwargs))
  File "/Users/rblack/_dev/nffs-symposium/live-2022/.direnv/python-3.8.12/lib/python3.8/site-packages/nbclient/util.py", line 62, in just_run
    return loop.run_until_complete(coro)
  File "/usr/local/Cellar/python@3.8/3.8.12_1/Frameworks/Python.framework/Versions/3.8/lib/python3.8/asyncio/base_events.py", line 616, in run_until_complete
    return future.result()
  File "/Users/rblack/_dev/nffs-symposium/live-2022/.direnv/python-3.8.12/lib/python3.8/site-packages/nbclient/client.py", line 559, in async_execute
    await self.async_execute_cell(
  File "/Users/rblack/_dev/nffs-symposium/live-2022/.direnv/python-3.8.12/lib/python3.8/site-packages/nbclient/client.py", line 854, in async_execute_cell
    self._check_raise_for_error(cell, exec_reply)
  File "/Users/rblack/_dev/nffs-symposium/live-2022/.direnv/python-3.8.12/lib/python3.8/site-packages/nbclient/client.py", line 756, in _check_raise_for_error
    raise CellExecutionError.from_cell_and_msg(cell, exec_reply_content)
nbclient.exceptions.CellExecutionError: An error occurred while executing the following cell:
------------------
import sys
sys.path.append('../mmflight')
from arc3 import CL
print(CL.y)
------------------

[0;31m---------------------------------------------------------------------------[0m
[0;31mModuleNotFoundError[0m                       Traceback (most recent call last)
[0;32m/var/folders/t9/hc5s57h95tj3rsp4qvk61m8m0000gn/T/ipykernel_11109/1774424401.py[0m in [0;36m<module>[0;34m[0m
[1;32m      1[0m [0;32mimport[0m [0msys[0m[0;34m[0m[0;34m[0m[0m
[1;32m      2[0m [0msys[0m[0;34m.[0m[0mpath[0m[0;34m.[0m[0mappend[0m[0;34m([0m[0;34m'../mmflight'[0m[0;34m)[0m[0;34m[0m[0;34m[0m[0m
[0;32m----> 3[0;31m [0;32mfrom[0m [0marc3[0m [0;32mimport[0m [0mCL[0m[0;34m[0m[0;34m[0m[0m
[0m[1;32m      4[0m [0mprint[0m[0;34m([0m[0mCL[0m[0;34m.[0m[0my[0m[0;34m)[0m[0;34m[0m[0;34m[0m[0m

[0;31mModuleNotFoundError[0m: No module named 'arc3'
ModuleNotFoundError: No module named 'arc3'

