Traceback (most recent call last):
  File "/Users/rblack/_dev/nffs-symposium/live-2022/.direnv/python-3.9.9/lib/python3.9/site-packages/jupyter_cache/executors/utils.py", line 51, in single_nb_execution
    executenb(
  File "/Users/rblack/_dev/nffs-symposium/live-2022/.direnv/python-3.9.9/lib/python3.9/site-packages/nbclient/client.py", line 1093, in execute
    return NotebookClient(nb=nb, resources=resources, km=km, **kwargs).execute()
  File "/Users/rblack/_dev/nffs-symposium/live-2022/.direnv/python-3.9.9/lib/python3.9/site-packages/nbclient/util.py", line 84, in wrapped
    return just_run(coro(*args, **kwargs))
  File "/Users/rblack/_dev/nffs-symposium/live-2022/.direnv/python-3.9.9/lib/python3.9/site-packages/nbclient/util.py", line 62, in just_run
    return loop.run_until_complete(coro)
  File "/usr/local/Cellar/python@3.9/3.9.9/Frameworks/Python.framework/Versions/3.9/lib/python3.9/asyncio/base_events.py", line 642, in run_until_complete
    return future.result()
  File "/Users/rblack/_dev/nffs-symposium/live-2022/.direnv/python-3.9.9/lib/python3.9/site-packages/nbclient/client.py", line 559, in async_execute
    await self.async_execute_cell(
  File "/Users/rblack/_dev/nffs-symposium/live-2022/.direnv/python-3.9.9/lib/python3.9/site-packages/nbclient/client.py", line 854, in async_execute_cell
    self._check_raise_for_error(cell, exec_reply)
  File "/Users/rblack/_dev/nffs-symposium/live-2022/.direnv/python-3.9.9/lib/python3.9/site-packages/nbclient/client.py", line 756, in _check_raise_for_error
    raise CellExecutionError.from_cell_and_msg(cell, exec_reply_content)
nbclient.exceptions.CellExecutionError: An error occurred while executing the following cell:
------------------
from mmtime.StdAtm import Air
import pint
u = pint.UnitRegistry()
------------------

Traceback [0;36m(most recent call last)[0m:

  File [1;32m"/Users/rblack/_dev/nffs-symposium/live-2022/.direnv/python-3.9.9/lib/python3.9/site-packages/IPython/core/interactiveshell.py"[0m, line [1;32m3457[0m, in [1;35mrun_code[0m
    exec(code_obj, self.user_global_ns, self.user_ns)

[0;36m  File [0;32m"/var/folders/t9/hc5s57h95tj3rsp4qvk61m8m0000gn/T/ipykernel_44397/330856896.py"[0;36m, line [0;32m1[0;36m, in [0;35m<module>[0;36m[0m
[0;31m    from mmtime.StdAtm import Air[0m

[0;36m  File [0;32m"/Users/rblack/_dev/nffs-symposium/live-2022/mmtime/StdAtm.py"[0;36m, line [0;32m24[0m
[0;31m    print(p)osawatomie-std-atm.png[0m
[0m            ^[0m
[0;31mSyntaxError[0m[0;31m:[0m invalid syntax

SyntaxError: invalid syntax (StdAtm.py, line 24)

