Traceback (most recent call last):
  File "/Users/rblack/_dev/live-2022/.direnv/python-3.10.5/lib/python3.10/site-packages/jupyter_cache/executors/utils.py", line 51, in single_nb_execution
    executenb(
  File "/Users/rblack/_dev/live-2022/.direnv/python-3.10.5/lib/python3.10/site-packages/nbclient/client.py", line 1093, in execute
    return NotebookClient(nb=nb, resources=resources, km=km, **kwargs).execute()
  File "/Users/rblack/_dev/live-2022/.direnv/python-3.10.5/lib/python3.10/site-packages/nbclient/util.py", line 84, in wrapped
    return just_run(coro(*args, **kwargs))
  File "/Users/rblack/_dev/live-2022/.direnv/python-3.10.5/lib/python3.10/site-packages/nbclient/util.py", line 62, in just_run
    return loop.run_until_complete(coro)
  File "/usr/local/Cellar/python@3.10/3.10.5/Frameworks/Python.framework/Versions/3.10/lib/python3.10/asyncio/base_events.py", line 646, in run_until_complete
    return future.result()
  File "/Users/rblack/_dev/live-2022/.direnv/python-3.10.5/lib/python3.10/site-packages/nbclient/client.py", line 559, in async_execute
    await self.async_execute_cell(
  File "/Users/rblack/_dev/live-2022/.direnv/python-3.10.5/lib/python3.10/site-packages/nbclient/client.py", line 854, in async_execute_cell
    self._check_raise_for_error(cell, exec_reply)
  File "/Users/rblack/_dev/live-2022/.direnv/python-3.10.5/lib/python3.10/site-packages/nbclient/client.py", line 756, in _check_raise_for_error
    raise CellExecutionError.from_cell_and_msg(cell, exec_reply_content)
nbclient.exceptions.CellExecutionError: An error occurred while executing the following cell:
------------------
command(ps,"quit")
------------------

[0;31m---------------------------------------------------------------------------[0m
[0;31mValueError[0m                                Traceback (most recent call last)
[0;32m/var/folders/ws/5h_x4h713cg8w0jmrm5_tfzc0000gn/T/ipykernel_26003/1255961134.py[0m in [0;36m<module>[0;34m[0m
[0;32m----> 1[0;31m [0mcommand[0m[0;34m([0m[0mps[0m[0;34m,[0m[0;34m"quit"[0m[0;34m)[0m[0;34m[0m[0;34m[0m[0m
[0m
[0;32m/var/folders/ws/5h_x4h713cg8w0jmrm5_tfzc0000gn/T/ipykernel_26003/1747104879.py[0m in [0;36mcommand[0;34m(process, cmd)[0m
[1;32m      1[0m [0;32mdef[0m [0mcommand[0m[0;34m([0m[0mprocess[0m[0;34m,[0m [0mcmd[0m[0;34m)[0m[0;34m:[0m[0;34m[0m[0;34m[0m[0m
[1;32m      2[0m     [0;34m"""send a command to a subprocess"""[0m[0;34m[0m[0;34m[0m[0m
[0;32m----> 3[0;31m     [0;34m([0m[0mout[0m[0;34m,[0m[0merr[0m[0;34m)[0m [0;34m=[0m [0mprocess[0m[0;34m.[0m[0mcommunicate[0m[0;34m([0m[0mbytes[0m[0;34m([0m[0mcmd[0m [0;34m+[0m [0;34m"\n"[0m[0;34m,[0m[0;34m'utf-8'[0m[0;34m)[0m[0;34m)[0m[0;34m[0m[0;34m[0m[0m
[0m[1;32m      4[0m     [0mprint[0m[0;34m([0m[0mout[0m[0;34m.[0m[0mdecode[0m[0;34m([0m[0;34m'utf-8'[0m[0;34m)[0m[0;34m)[0m[0;34m[0m[0;34m[0m[0m

[0;32m/usr/local/Cellar/python@3.10/3.10.5/Frameworks/Python.framework/Versions/3.10/lib/python3.10/subprocess.py[0m in [0;36mcommunicate[0;34m(self, input, timeout)[0m
[1;32m   1125[0m [0;34m[0m[0m
[1;32m   1126[0m         [0;32mif[0m [0mself[0m[0;34m.[0m[0m_communication_started[0m [0;32mand[0m [0minput[0m[0;34m:[0m[0;34m[0m[0;34m[0m[0m
[0;32m-> 1127[0;31m             [0;32mraise[0m [0mValueError[0m[0;34m([0m[0;34m"Cannot send input after starting communication"[0m[0;34m)[0m[0;34m[0m[0;34m[0m[0m
[0m[1;32m   1128[0m [0;34m[0m[0m
[1;32m   1129[0m         [0;31m# Optimization: If we are not worried about timeouts, we haven't[0m[0;34m[0m[0;34m[0m[0m

[0;31mValueError[0m: Cannot send input after starting communication
ValueError: Cannot send input after starting communication

