Traceback (most recent call last):
  File "/Users/rblack/_dev/nffs-symposium/live-2022/.direnv/python-3.9.9/lib/python3.9/site-packages/jupyter_cache/executors/utils.py", line 51, in single_nb_execution
    executenb(
  File "/Users/rblack/_dev/nffs-symposium/live-2022/.direnv/python-3.9.9/lib/python3.9/site-packages/nbclient/client.py", line 1093, in execute
    return NotebookClient(nb=nb, resources=resources, km=km, **kwargs).execute()
  File "/Users/rblack/_dev/nffs-symposium/live-2022/.direnv/python-3.9.9/lib/python3.9/site-packages/nbclient/util.py", line 84, in wrapped
    return just_run(coro(*args, **kwargs))
  File "/Users/rblack/_dev/nffs-symposium/live-2022/.direnv/python-3.9.9/lib/python3.9/site-packages/nbclient/util.py", line 62, in just_run
    return loop.run_until_complete(coro)
  File "/usr/local/Cellar/python@3.9/3.9.9/Frameworks/Python.framework/Versions/3.9/lib/python3.9/asyncio/base_events.py", line 642, in run_until_complete
    return future.result()
  File "/Users/rblack/_dev/nffs-symposium/live-2022/.direnv/python-3.9.9/lib/python3.9/site-packages/nbclient/client.py", line 559, in async_execute
    await self.async_execute_cell(
  File "/Users/rblack/_dev/nffs-symposium/live-2022/.direnv/python-3.9.9/lib/python3.9/site-packages/nbclient/client.py", line 854, in async_execute_cell
    self._check_raise_for_error(cell, exec_reply)
  File "/Users/rblack/_dev/nffs-symposium/live-2022/.direnv/python-3.9.9/lib/python3.9/site-packages/nbclient/client.py", line 756, in _check_raise_for_error
    raise CellExecutionError.from_cell_and_msg(cell, exec_reply_content)
nbclient.exceptions.CellExecutionError: An error occurred while executing the following cell:
------------------
fn_t = fit_curve(rpm_x, rpm_y)
n_t = fn_t(time)

max_time = rpm_x[-1]
t_samples = np.linspace(0, max_time, 50)
rpm_samples = fn_t(t_samples)
show_curve(t_samples, rpm_samples, "RPM Function", "Time (min)", "RPM")
------------------

[0;31m---------------------------------------------------------------------------[0m
[0;31mNameError[0m                                 Traceback (most recent call last)
[0;32m/var/folders/t9/hc5s57h95tj3rsp4qvk61m8m0000gn/T/ipykernel_47928/43273090.py[0m in [0;36m<module>[0;34m[0m
[1;32m      1[0m [0mfn_t[0m [0;34m=[0m [0mfit_curve[0m[0;34m([0m[0mrpm_x[0m[0;34m,[0m [0mrpm_y[0m[0;34m)[0m[0;34m[0m[0;34m[0m[0m
[0;32m----> 2[0;31m [0mn_t[0m [0;34m=[0m [0mfn_t[0m[0;34m([0m[0mtime[0m[0;34m)[0m[0;34m[0m[0;34m[0m[0m
[0m[1;32m      3[0m [0;34m[0m[0m
[1;32m      4[0m [0mmax_time[0m [0;34m=[0m [0mrpm_x[0m[0;34m[[0m[0;34m-[0m[0;36m1[0m[0;34m][0m[0;34m[0m[0;34m[0m[0m
[1;32m      5[0m [0mt_samples[0m [0;34m=[0m [0mnp[0m[0;34m.[0m[0mlinspace[0m[0;34m([0m[0;36m0[0m[0;34m,[0m [0mmax_time[0m[0;34m,[0m [0;36m50[0m[0;34m)[0m[0;34m[0m[0;34m[0m[0m

[0;31mNameError[0m: name 'time' is not defined
NameError: name 'time' is not defined

